import AppError from '@shared/errors/AppError';
import FakeAppointmentsRepository from '../repositories/fakes/FakeAppointmentsRepository';
import CreateAppointmentsService from './CreateAppointmentService';

describe('CreateAppointment', () => {
  it('should be able to create a new appointment', async () => {
    const fakeAppointmentsRepository = new FakeAppointmentsRepository();
    const createAppointment = new CreateAppointmentsService(
      fakeAppointmentsRepository,
    );

    const appointment = await createAppointment.execute({
      date: new Date(),
      provider_id: '121212',
    });

    expect(appointment).toHaveProperty('id');
    expect(appointment.provider_id).toBe('121212');
  });

  // Esse teste espera que caia em um try
  it('should not be able to create a two appointment at the same time', async () => {
    const fakeAppointmentsRepository = new FakeAppointmentsRepository();
    const createAppointment = new CreateAppointmentsService(
      fakeAppointmentsRepository,
    );

    const appointmentDate = new Date(2020, 4, 10, 11);

    await createAppointment.execute({
      date: appointmentDate,
      provider_id: '121212',
    });

    // Espera que caia em um erro do tipo AppError
    expect(
      createAppointment.execute({
        date: appointmentDate,
        provider_id: '121212',
      }),
    ).rejects.toBeInstanceOf(AppError);
  });
});
